<?xml version="1.0" ?>
<!-- =================================================================================== -->
<!-- |    This document was autogenerated by xacro from /home/elyar/moveit_kinova/src/kortex_description/robots/gen3_robotiq_2f_140.xacro | -->
<!-- |    EDITING THIS FILE BY HAND IS NOT RECOMMENDED                                 | -->
<!-- =================================================================================== -->
<robot name="gen3_robotiq_2f_140">
    <!-- Run the macros -->
    <link name="world" />
    <joint name="world_to_root" type="fixed">
        <child link="base_link" />
        <parent link="world" />
        <origin rpy="0 0 0" xyz="0 0 0" />
    </joint>
    <link name="base_link">
        <!-- <inertial>
          <origin xyz="-0.000648 -0.000166 0.084487" rpy="0 0 0" />
          <mass value="1.697" />
          <inertia ixx="0.004622" ixy="9E-06" ixz="6E-05" iyy="0.004495" iyz="9E-06" izz="0.002079" />
        </inertial> -->
        <visual>
            <origin rpy="0 0 0" xyz="0 0 0" />
            <geometry>
                <mesh filename="package://kortex_description/arms/gen3/7dof/meshes/base_link.STL" />
            </geometry>
            <material name="">
                <color rgba="0.75294 0.75294 0.75294 1" />
            </material>
        </visual>
        <collision>
            <origin rpy="0 0 0" xyz="0 0 0" />
            <geometry>
                <mesh filename="package://kortex_description/arms/gen3/7dof/meshes/base_link.STL" />
            </geometry>
        </collision>
        <inertial>
            <mass value="0.1" />
            <origin xyz="0 0 0" rpy="0 0 0" />
            <inertia ixx="0.03" iyy="0.03" izz="0.03" ixy="0.0" ixz="0.0" iyz="0.0" />
        </inertial>
    </link>
    <link name="shoulder_link">
        <inertial>
            <origin rpy="0 0 0" xyz="-2.3E-05 -0.010364 -0.07336" />
            <mass value="1.3773" />
            <inertia ixx="0.00457" ixy="1E-06" ixz="2E-06" iyy="0.004831" iyz="0.000448" izz="0.001409" />
        </inertial>
        <visual>
            <origin rpy="0 0 0" xyz="0 0 0" />
            <geometry>
                <mesh filename="package://kortex_description/arms/gen3/7dof/meshes/shoulder_link.STL" />
            </geometry>
            <material name="">
                <color rgba="0.75294 0.75294 0.75294 1" />
            </material>
        </visual>
        <collision>
            <origin rpy="0 0 0" xyz="0 0 0" />
            <geometry>
                <mesh filename="package://kortex_description/arms/gen3/7dof/meshes/shoulder_link.STL" />
            </geometry>
        </collision>
    </link>
    <joint name="joint_1" type="continuous">
        <origin rpy="3.1416 2.7629E-18 -4.9305E-36" xyz="0 0 0.15643" />
        <parent link="base_link" />
        <child link="shoulder_link" />
        <axis xyz="0 0 1" />
        <limit effort="39" velocity="1.3963" />
    </joint>
    <link name="half_arm_1_link">
        <inertial>
            <origin rpy="0 0 0" xyz="-4.4E-05 -0.09958 -0.013278" />
            <mass value="1.1636" />
            <inertia ixx="0.011088" ixy="5E-06" ixz="0" iyy="0.001072" iyz="-0.000691" izz="0.011255" />
        </inertial>
        <visual>
            <origin rpy="0 0 0" xyz="0 0 0" />
            <geometry>
                <mesh filename="package://kortex_description/arms/gen3/7dof/meshes/half_arm_1_link.STL" />
            </geometry>
            <material name="">
                <color rgba="0.75294 0.75294 0.75294 1" />
            </material>
        </visual>
        <collision>
            <origin rpy="0 0 0" xyz="0 0 0" />
            <geometry>
                <mesh filename="package://kortex_description/arms/gen3/7dof/meshes/half_arm_1_link.STL" />
            </geometry>
        </collision>
    </link>
    <joint name="joint_2" type="revolute">
        <origin rpy="1.5708 2.1343E-17 -1.1102E-16" xyz="0 0.005375 -0.12838" />
        <parent link="shoulder_link" />
        <child link="half_arm_1_link" />
        <axis xyz="0 0 1" />
        <limit effort="39" lower="-2.41" upper="2.41" velocity="1.3963" />
    </joint>
    <link name="half_arm_2_link">
        <inertial>
            <origin rpy="0 0 0" xyz="-4.4E-05 -0.006641 -0.117892" />
            <mass value="1.1636" />
            <inertia ixx="0.010932" ixy="0" ixz="-7E-06" iyy="0.011127" iyz="0.000606" izz="0.001043" />
        </inertial>
        <visual>
            <origin rpy="0 0 0" xyz="0 0 0" />
            <geometry>
                <mesh filename="package://kortex_description/arms/gen3/7dof/meshes/half_arm_2_link.STL" />
            </geometry>
            <material name="">
                <color rgba="0.75294 0.75294 0.75294 1" />
            </material>
        </visual>
        <collision>
            <origin rpy="0 0 0" xyz="0 0 0" />
            <geometry>
                <mesh filename="package://kortex_description/arms/gen3/7dof/meshes/half_arm_2_link.STL" />
            </geometry>
        </collision>
    </link>
    <joint name="joint_3" type="continuous">
        <origin rpy="-1.5708 1.2326E-32 -2.9122E-16" xyz="0 -0.21038 -0.006375" />
        <parent link="half_arm_1_link" />
        <child link="half_arm_2_link" />
        <axis xyz="0 0 1" />
        <limit effort="39" velocity="1.3963" />
    </joint>
    <link name="forearm_link">
        <inertial>
            <origin rpy="0 0 0" xyz="-1.8E-05 -0.075478 -0.015006" />
            <mass value="0.9302" />
            <inertia ixx="0.008147" ixy="-1E-06" ixz="0" iyy="0.000631" iyz="-0.0005" izz="0.008316" />
        </inertial>
        <visual>
            <origin rpy="0 0 0" xyz="0 0 0" />
            <geometry>
                <mesh filename="package://kortex_description/arms/gen3/7dof/meshes/forearm_link.STL" />
            </geometry>
            <material name="">
                <color rgba="0.75294 0.75294 0.75294 1" />
            </material>
        </visual>
        <collision>
            <origin rpy="0 0 0" xyz="0 0 0" />
            <geometry>
                <mesh filename="package://kortex_description/arms/gen3/7dof/meshes/forearm_link.STL" />
            </geometry>
        </collision>
    </link>
    <joint name="joint_4" type="revolute">
        <origin rpy="1.5708 -6.6954E-17 -1.6653E-16" xyz="0 0.006375 -0.21038" />
        <parent link="half_arm_2_link" />
        <child link="forearm_link" />
        <axis xyz="0 0 1" />
        <limit effort="39" lower="-2.66" upper="2.66" velocity="1.3963" />
    </joint>
    <link name="spherical_wrist_1_link">
        <inertial>
            <origin rpy="0 0 0" xyz="1E-06 -0.009432 -0.063883" />
            <mass value="0.6781" />
            <inertia ixx="0.001596" ixy="0" ixz="0" iyy="0.001607" iyz="0.000256" izz="0.000399" />
        </inertial>
        <visual>
            <origin rpy="0 0 0" xyz="0 0 0" />
            <geometry>
                <mesh filename="package://kortex_description/arms/gen3/7dof/meshes/spherical_wrist_1_link.STL" />
            </geometry>
            <material name="">
                <color rgba="0.75294 0.75294 0.75294 1" />
            </material>
        </visual>
        <collision>
            <origin rpy="0 0 0" xyz="0 0 0" />
            <geometry>
                <mesh filename="package://kortex_description/arms/gen3/7dof/meshes/spherical_wrist_1_link.STL" />
            </geometry>
        </collision>
    </link>
    <joint name="joint_5" type="continuous">
        <origin rpy="-1.5708 2.2204E-16 -6.373E-17" xyz="0 -0.20843 -0.006375" />
        <parent link="forearm_link" />
        <child link="spherical_wrist_1_link" />
        <axis xyz="0 0 1" />
        <limit effort="9" velocity="1.2218" />
    </joint>
    <link name="spherical_wrist_2_link">
        <inertial>
            <origin rpy="0 0 0" xyz="1E-06 -0.045483 -0.00965" />
            <mass value="0.6781" />
            <inertia ixx="0.001641" ixy="0" ixz="0" iyy="0.00041" iyz="-0.000278" izz="0.001641" />
        </inertial>
        <visual>
            <origin rpy="0 0 0" xyz="0 0 0" />
            <geometry>
                <mesh filename="package://kortex_description/arms/gen3/7dof/meshes/spherical_wrist_2_link.STL" />
            </geometry>
            <material name="">
                <color rgba="0.75294 0.75294 0.75294 1" />
            </material>
        </visual>
        <collision>
            <origin rpy="0 0 0" xyz="0 0 0" />
            <geometry>
                <mesh filename="package://kortex_description/arms/gen3/7dof/meshes/spherical_wrist_2_link.STL" />
            </geometry>
        </collision>
    </link>
    <joint name="joint_6" type="revolute">
        <origin rpy="1.5708 9.2076E-28 -8.2157E-15" xyz="0 0.00017505 -0.10593" />
        <parent link="spherical_wrist_1_link" />
        <child link="spherical_wrist_2_link" />
        <axis xyz="0 0 1" />
        <limit effort="9" lower="-2.23" upper="2.23" velocity="1.2218" />
    </joint>
    <link name="bracelet_link">
        <inertial>
            <origin rpy="0 0 0" xyz="-9.3E-05 0.000132 -0.022905" />
            <mass value="0.364" />
            <inertia ixx="0.000214" ixy="0" ixz="1E-06" iyy="0.000223" iyz="-2E-06" izz="0.00024" />
        </inertial>
        <visual>
            <origin rpy="0 0 0" xyz="0 0 0" />
            <geometry>
                <mesh filename="package://kortex_description/arms/gen3/7dof/meshes/bracelet_no_vision_link.STL" />
            </geometry>
            <material name="">
                <color rgba="0.75294 0.75294 0.75294 1" />
            </material>
        </visual>
        <collision>
            <origin rpy="0 0 0" xyz="0 0 0" />
            <geometry>
                <mesh filename="package://kortex_description/arms/gen3/7dof/meshes/bracelet_no_vision_link.STL" />
            </geometry>
        </collision>
    </link>
    <joint name="joint_7" type="continuous">
        <origin rpy="-1.5708 -5.5511E-17 9.6396E-17" xyz="0 -0.10593 -0.00017505" />
        <parent link="spherical_wrist_2_link" />
        <child link="bracelet_link" />
        <axis xyz="0 0 1" />
        <limit effort="9" velocity="1.2218" />
    </joint>
    <link name="end_effector_link" />
    <joint name="end_effector" type="fixed">
        <origin rpy="3.14159265358979 1.09937075168372E-32 0" xyz="0 0 -0.0615250000000001" />
        <parent link="bracelet_link" />
        <child link="end_effector_link" />
        <axis xyz="0 0 0" />
    </joint>
    <!-- PALM LINK AND JOINT -->
    <link name="palm_link">
        <inertial>
            <origin xyz="0 0 0.0386" rpy="0 0 0" />
            <mass value="1.0288" />
            <!-- density 1652.3 kg/m3 adjusted to have final total mass of 1.95 -->
            <inertia ixx="0.0011896" ixy="0.0" ixz="0.0" iyy="0.0011889" iyz="0.0" izz="0.0015636" />
        </inertial>
        <visual>
            <origin rpy="0 0 0" xyz="0 0 0" />
            <geometry>
                <mesh filename="package://kortex_description/grippers/robotiq_2f_140/meshes/visual/palm.stl" />
            </geometry>
            <material name="">
                <color rgba="0.1 0.1 0.1 1" />
            </material>
        </visual>
        <collision>
            <origin rpy="0 0 0" xyz="0 0 0" />
            <geometry>
                <mesh filename="package://kortex_description/grippers/robotiq_2f_140/meshes/collision/palm_collision.stl" />
            </geometry>
        </collision>
    </link>
    <joint name="palm_joint" type="fixed">
        <parent link="end_effector_link" />
        <child link="palm_link" />
        <origin rpy="0.0 0.0 1.5707963267948966" xyz="0.0 0.0 0.0" />
    </joint>
    <gazebo reference="palm_link">
        <material>Gazebo/Black</material>
        <plugin name="gazebo_ros_control">
            <robotNamespace>/</robotNamespace>
        </plugin>
    </gazebo>
    <!-- FINGER 1 LINK AND JOINTS -->
    <!-- FINGER 2 LINKS AND JOINTS -->
    <!-- FINGER 3 LINKS AND JOINTS -->
    <!-- Tool frame used by the arm -->
    <link name="tool_frame" />
    <joint name="tool_frame_joint" type="fixed">
        <origin rpy="0 0 0" xyz="0 0 0.20" />
        <parent link="end_effector_link" />
        <child link="tool_frame" />
        <axis xyz="0 0 0" />
    </joint>
    <link name="left_finger_1">
        <inertial>
            <origin xyz="0.0 2.2105e-03 1.2155e-02" rpy="0 0 0" />
            <mass value="0.047" />
            <!-- density of aluminum -->
            <inertia ixx="1.5889e-05" ixy="0.0" ixz="0.0" iyy="6.9350e-06" iyz="-4.7500e-07" izz="1.4915e-05" />
        </inertial>
        <visual>
            <origin rpy="0 0 0" xyz="0 0 0" />
            <geometry>
                <mesh filename="package://kortex_description/grippers/robotiq_2f_140/meshes/visual/knuckle.stl" />
            </geometry>
            <material name="">
                <color rgba="0.792156862745098 0.819607843137255 0.933333333333333 1" />
            </material>
        </visual>
        <collision>
            <origin rpy="0 0 0" xyz="0 0 0" />
            <geometry>
                <mesh filename="package://kortex_description/grippers/robotiq_2f_140/meshes/collision/knuckle_collision.stl" />
            </geometry>
        </collision>
    </link>
    <gazebo reference="left_finger_1">
        <visual>
            <material>
                <ambient>0.792156862745098 0.819607843137255 0.933333333333333 1</ambient>
                <diffuse>0.792156862745098 0.819607843137255 0.933333333333333 1</diffuse>
            </material>
        </visual>
    </gazebo>
    <link name="left_finger_2">
        <inertial>
            <origin xyz="0.0007467 -0.0000378 0.0430192" rpy="0 0 0" />
            <mass value="0.167" />
            <!-- density of aluminum -->
            <inertia ixx="1.5920e-04" ixy="0.0" ixz="-2.3750e-08" iyy="1.5903e-04" iyz="9.3100e-06" izz="1.9142e-05" />
        </inertial>
        <visual>
            <origin rpy="0 0 0" xyz="0 0 0" />
            <geometry>
                <mesh filename="package://kortex_description/grippers/robotiq_2f_140/meshes/visual/finger.stl" />
            </geometry>
            <material name="">
                <color rgba="0.1 0.1 0.1 1" />
            </material>
        </visual>
        <collision>
            <origin rpy="0 0 0" xyz="0 0 0" />
            <geometry>
                <mesh filename="package://kortex_description/grippers/robotiq_2f_140/meshes/visual/finger.stl" />
            </geometry>
        </collision>
    </link>
    <gazebo reference="left_finger_2">
        <material>Gazebo/White</material>
    </gazebo>
    <link name="left_finger_3">
        <inertial>
            <origin xyz="0.0007467 -0.0000378 0.0430192" rpy="0 0 0" />
            <mass value="0.0929" />
            <!-- density of aluminum -->
            <inertia ixx="4.2323e-05" ixy="1.9000e-07" ixz="-5.2250e-07" iyy="3.9734e-05" iyz="5.7950e-06" izz="1.1210e-05" />
        </inertial>
        <visual>
            <origin rpy="0 0 0" xyz="0 0 0" />
            <geometry>
                <mesh filename="package://kortex_description/grippers/robotiq_2f_140/meshes/visual/finger_tip.stl" />
            </geometry>
            <material name="">
                <color rgba="0.1 0.1 0.1 1" />
            </material>
        </visual>
        <collision>
            <origin rpy="0 0 0" xyz="0 0 0" />
            <geometry>
                <mesh filename="package://kortex_description/grippers/robotiq_2f_140/meshes/visual/finger_tip.stl" />
            </geometry>
        </collision>
    </link>
    <gazebo reference="left_finger_3">
        <material>Gazebo/White</material>
    </gazebo>
    <link name="right_finger_1">
        <inertial>
            <origin xyz="0.0 2.2105e-03 1.2155e-02" rpy="0 0 0" />
            <mass value="0.047" />
            <!-- density of aluminum -->
            <inertia ixx="1.5889e-05" ixy="0.0" ixz="0.0" iyy="6.9350e-06" iyz="-4.7500e-07" izz="1.4915e-05" />
        </inertial>
        <visual>
            <origin rpy="0 0 0" xyz="0 0 0" />
            <geometry>
                <mesh filename="package://kortex_description/grippers/robotiq_2f_140/meshes/visual/knuckle.stl" />
            </geometry>
            <material name="">
                <color rgba="0.792156862745098 0.819607843137255 0.933333333333333 1" />
            </material>
        </visual>
        <collision>
            <origin rpy="0 0 0" xyz="0 0 0" />
            <geometry>
                <mesh filename="package://kortex_description/grippers/robotiq_2f_140/meshes/collision/knuckle_collision.stl" />
            </geometry>
        </collision>
    </link>
    <gazebo reference="right_finger_1">
        <visual>
            <material>
                <ambient>0.792156862745098 0.819607843137255 0.933333333333333 1</ambient>
                <diffuse>0.792156862745098 0.819607843137255 0.933333333333333 1</diffuse>
            </material>
        </visual>
    </gazebo>
    <link name="right_finger_2">
        <inertial>
            <origin xyz="0.0007467 -0.0000378 0.0430192" rpy="0 0 0" />
            <mass value="0.167" />
            <!-- density of aluminum -->
            <inertia ixx="1.5920e-04" ixy="0.0" ixz="-2.3750e-08" iyy="1.5903e-04" iyz="9.3100e-06" izz="1.9142e-05" />
        </inertial>
        <visual>
            <origin rpy="0 0 0" xyz="0 0 0" />
            <geometry>
                <mesh filename="package://kortex_description/grippers/robotiq_2f_140/meshes/visual/finger.stl" />
            </geometry>
            <material name="">
                <color rgba="0.1 0.1 0.1 1" />
            </material>
        </visual>
        <collision>
            <origin rpy="0 0 0" xyz="0 0 0" />
            <geometry>
                <mesh filename="package://kortex_description/grippers/robotiq_2f_140/meshes/visual/finger.stl" />
            </geometry>
        </collision>
    </link>
    <gazebo reference="right_finger_2">
        <material>Gazebo/White</material>
    </gazebo>
    <link name="right_finger_3">
        <inertial>
            <origin xyz="0.0007467 -0.0000378 0.0430192" rpy="0 0 0" />
            <mass value="0.0929" />
            <!-- density of aluminum -->
            <inertia ixx="4.2323e-05" ixy="1.9000e-07" ixz="-5.2250e-07" iyy="3.9734e-05" iyz="5.7950e-06" izz="1.1210e-05" />
        </inertial>
        <visual>
            <origin rpy="0 0 0" xyz="0 0 0" />
            <geometry>
                <mesh filename="package://kortex_description/grippers/robotiq_2f_140/meshes/visual/finger_tip.stl" />
            </geometry>
            <material name="">
                <color rgba="0.1 0.1 0.1 1" />
            </material>
        </visual>
        <collision>
            <origin rpy="0 0 0" xyz="0 0 0" />
            <geometry>
                <mesh filename="package://kortex_description/grippers/robotiq_2f_140/meshes/visual/finger_tip.stl" />
            </geometry>
        </collision>
    </link>
    <gazebo reference="right_finger_3">
        <material>Gazebo/White</material>
    </gazebo>
    <link name="middle_finger_1">
        <inertial>
            <origin xyz="0.0 2.2105e-03 1.2155e-02" rpy="0 0 0" />
            <mass value="0.047" />
            <!-- density of aluminum -->
            <inertia ixx="1.5889e-05" ixy="0.0" ixz="0.0" iyy="6.9350e-06" iyz="-4.7500e-07" izz="1.4915e-05" />
        </inertial>
        <visual>
            <origin rpy="0 0 0" xyz="0 0 0" />
            <geometry>
                <mesh filename="package://kortex_description/grippers/robotiq_2f_140/meshes/visual/knuckle.stl" />
            </geometry>
            <material name="">
                <color rgba="0.792156862745098 0.819607843137255 0.933333333333333 1" />
            </material>
        </visual>
        <collision>
            <origin rpy="0 0 0" xyz="0 0 0" />
            <geometry>
                <mesh filename="package://kortex_description/grippers/robotiq_2f_140/meshes/collision/knuckle_collision.stl" />
            </geometry>
        </collision>
    </link>
    <gazebo reference="middle_finger_1">
        <visual>
            <material>
                <ambient>0.792156862745098 0.819607843137255 0.933333333333333 1</ambient>
                <diffuse>0.792156862745098 0.819607843137255 0.933333333333333 1</diffuse>
            </material>
        </visual>
    </gazebo>
    <link name="middle_finger_2">
        <inertial>
            <origin xyz="0.0007467 -0.0000378 0.0430192" rpy="0 0 0" />
            <mass value="0.167" />
            <!-- density of aluminum -->
            <inertia ixx="1.5920e-04" ixy="0.0" ixz="-2.3750e-08" iyy="1.5903e-04" iyz="9.3100e-06" izz="1.9142e-05" />
        </inertial>
        <visual>
            <origin rpy="0 0 0" xyz="0 0 0" />
            <geometry>
                <mesh filename="package://kortex_description/grippers/robotiq_2f_140/meshes/visual/finger.stl" />
            </geometry>
            <material name="">
                <color rgba="0.1 0.1 0.1 1" />
            </material>
        </visual>
        <collision>
            <origin rpy="0 0 0" xyz="0 0 0" />
            <geometry>
                <mesh filename="package://kortex_description/grippers/robotiq_2f_140/meshes/visual/finger.stl" />
            </geometry>
        </collision>
    </link>
    <gazebo reference="middle_finger_2">
        <material>Gazebo/White</material>
    </gazebo>
    <link name="middle_finger_3">
        <inertial>
            <origin xyz="0.0007467 -0.0000378 0.0430192" rpy="0 0 0" />
            <mass value="0.0929" />
            <!-- density of aluminum -->
            <inertia ixx="4.2323e-05" ixy="1.9000e-07" ixz="-5.2250e-07" iyy="3.9734e-05" iyz="5.7950e-06" izz="1.1210e-05" />
        </inertial>
        <visual>
            <origin rpy="0 0 0" xyz="0 0 0" />
            <geometry>
                <mesh filename="package://kortex_description/grippers/robotiq_2f_140/meshes/visual/finger_tip.stl" />
            </geometry>
            <material name="">
                <color rgba="0.1 0.1 0.1 1" />
            </material>
        </visual>
        <collision>
            <origin rpy="0 0 0" xyz="0 0 0" />
            <geometry>
                <mesh filename="package://kortex_description/grippers/robotiq_2f_140/meshes/visual/finger_tip.stl" />
            </geometry>
        </collision>
    </link>
    <gazebo reference="middle_finger_3">
        <material>Gazebo/White</material>
    </gazebo>
    <joint name="left_finger_1_joint" type="revolute">
        <origin rpy="0 0 3.14159265" xyz="0.01905 0.033 0.0745" />
        <parent link="palm_link" />
        <child link="left_finger_1" />
        <axis xyz="0 0 1" />
        <limit effort="100" lower="0" upper="1.570796327" velocity="5" />
    </joint>
    <joint name="left_finger_2_joint" type="revolute">
        <origin rpy="0 0 0" xyz="0 0 0.0165" />
        <parent link="left_finger_1" />
        <child link="left_finger_2" />
        <axis xyz="0 1 0" />
        <limit effort="100" lower="-1.570796327" upper="1.570796327" velocity="5" />
    </joint>
    <joint name="left_finger_3_joint" type="revolute">
        <origin rpy="0 0 0" xyz="0 0 0.0865" />
        <parent link="left_finger_2" />
        <child link="left_finger_3" />
        <axis xyz="0 1 0" />
        <limit effort="100" lower="-1.570796327" upper="1.570796327" velocity="5" />
    </joint>
    <joint name="right_finger_1_joint" type="revolute">
        <origin rpy="0 0 3.14159265" xyz="0.01905 -0.033 0.0745" />
        <parent link="palm_link" />
        <child link="right_finger_1" />
        <axis xyz="0 0 1" />
        <limit effort="100" lower="0" upper="1.570796327" velocity="5" />
        <mimic joint="left_finger_1_joint" multiplier="-1" offset="0" />
    </joint>
    <joint name="right_finger_2_joint" type="revolute">
        <origin rpy="0 0 0" xyz="0 0 0.0165" />
        <parent link="right_finger_1" />
        <child link="right_finger_2" />
        <axis xyz="0 1 0" />
        <limit effort="100" lower="-1.570796327" upper="1.570796327" velocity="5" />
    </joint>
    <joint name="right_finger_3_joint" type="revolute">
        <origin rpy="0 0 0" xyz="0 0 0.0865" />
        <parent link="right_finger_2" />
        <child link="right_finger_3" />
        <axis xyz="0 1 0" />
        <limit effort="100" lower="-1.570796327" upper="1.570796327" velocity="5" />
    </joint>
    <joint name="middle_finger_1_joint" type="fixed">
        <origin rpy="0 0 0" xyz="-0.03811 0 0.0745 " />
        <parent link="palm_link" />
        <child link="middle_finger_1" />
    </joint>
    <joint name="middle_finger_2_joint" type="revolute">
        <origin rpy="0 0 0" xyz="0 0 0.0165" />
        <parent link="middle_finger_1" />
        <child link="middle_finger_2" />
        <axis xyz="0 1 0" />
        <limit effort="100" lower="-1.570796327" upper="1.570796327" velocity="5" />
    </joint>
    <joint name="middle_finger_3_joint" type="revolute">
        <origin rpy="0 0 0" xyz="0 0 0.0865" />
        <parent link="middle_finger_2" />
        <child link="middle_finger_3" />
        <axis xyz="0 1 0" />
        <limit effort="100" lower="-1.570796327" upper="1.570796327" velocity="5" />
    </joint>
    <!-- Transmissions are loaded in the generic kortex xacro when simulation is enabled -->
    <!-- <xacro:robotiq_arg2f_transmission prefix="${prefix}"/> -->
    <transmission name="joint_1_transmission">
        <type>transmission_interface/SimpleTransmission</type>
        <joint name="joint_1">
            <hardwareInterface>hardware_interface/EffortJointInterface</hardwareInterface>
        </joint>
        <actuator name="joint_1_motor">
            <mechanicalReduction>1</mechanicalReduction>
            <hardwareInterface>hardware_interface/EffortJointInterface</hardwareInterface>
        </actuator>
    </transmission>
    <transmission name="joint_2_transmission">
        <type>transmission_interface/SimpleTransmission</type>
        <joint name="joint_2">
            <hardwareInterface>hardware_interface/EffortJointInterface</hardwareInterface>
        </joint>
        <actuator name="joint_2_motor">
            <mechanicalReduction>1</mechanicalReduction>
            <hardwareInterface>hardware_interface/EffortJointInterface</hardwareInterface>
        </actuator>
    </transmission>
    <transmission name="joint_3_transmission">
        <type>transmission_interface/SimpleTransmission</type>
        <joint name="joint_3">
            <hardwareInterface>hardware_interface/EffortJointInterface</hardwareInterface>
        </joint>
        <actuator name="joint_3_motor">
            <mechanicalReduction>1</mechanicalReduction>
            <hardwareInterface>hardware_interface/EffortJointInterface</hardwareInterface>
        </actuator>
    </transmission>
    <transmission name="joint_4_transmission">
        <type>transmission_interface/SimpleTransmission</type>
        <joint name="joint_4">
            <hardwareInterface>hardware_interface/EffortJointInterface</hardwareInterface>
        </joint>
        <actuator name="joint_4_motor">
            <mechanicalReduction>1</mechanicalReduction>
            <hardwareInterface>hardware_interface/EffortJointInterface</hardwareInterface>
        </actuator>
    </transmission>
    <transmission name="joint_5_transmission">
        <type>transmission_interface/SimpleTransmission</type>
        <joint name="joint_5">
            <hardwareInterface>hardware_interface/EffortJointInterface</hardwareInterface>
        </joint>
        <actuator name="joint_5_motor">
            <mechanicalReduction>1</mechanicalReduction>
            <hardwareInterface>hardware_interface/EffortJointInterface</hardwareInterface>
        </actuator>
    </transmission>
    <transmission name="joint_6_transmission">
        <type>transmission_interface/SimpleTransmission</type>
        <joint name="joint_6">
            <hardwareInterface>hardware_interface/EffortJointInterface</hardwareInterface>
        </joint>
        <actuator name="joint_6_motor">
            <mechanicalReduction>1</mechanicalReduction>
            <hardwareInterface>hardware_interface/EffortJointInterface</hardwareInterface>
        </actuator>
    </transmission>
    <transmission name="joint_7_transmission">
        <type>transmission_interface/SimpleTransmission</type>
        <joint name="joint_7">
            <hardwareInterface>hardware_interface/EffortJointInterface</hardwareInterface>
        </joint>
        <actuator name="joint_7_motor">
            <mechanicalReduction>1</mechanicalReduction>
            <hardwareInterface>hardware_interface/EffortJointInterface</hardwareInterface>
        </actuator>
    </transmission>
    <transmission name="left_finger_1_joint_trans">
        <type>transmission_interface/SimpleTransmission</type>
        <joint name="left_finger_1_joint">
            <hardwareInterface>hardware_interface/EffortJointInterface</hardwareInterface>
        </joint>
        <actuator name="left_finger_1_joint_motor">
            <mechanicalReduction>1</mechanicalReduction>
            <hardwareInterface>hardware_interface/EffortJointInterface</hardwareInterface>
        </actuator>
    </transmission>
    <transmission name="left_finger_2_joint_trans">
        <type>transmission_interface/SimpleTransmission</type>
        <joint name="left_finger_2_joint">
            <hardwareInterface>hardware_interface/EffortJointInterface</hardwareInterface>
        </joint>
        <actuator name="left_finger_2_joint_motor">
            <mechanicalReduction>1</mechanicalReduction>
            <hardwareInterface>hardware_interface/EffortJointInterface</hardwareInterface>
        </actuator>
    </transmission>
    <transmission name="left_finger_3_joint_trans">
        <type>transmission_interface/SimpleTransmission</type>
        <joint name="left_finger_3_joint">
            <hardwareInterface>hardware_interface/EffortJointInterface</hardwareInterface>
        </joint>
        <actuator name="left_finger_3_joint_motor">
            <mechanicalReduction>1</mechanicalReduction>
            <hardwareInterface>hardware_interface/EffortJointInterface</hardwareInterface>
        </actuator>
    </transmission>
    <transmission name="middle_finger_2_joint_trans">
        <type>transmission_interface/SimpleTransmission</type>
        <joint name="middle_finger_2_joint">
            <hardwareInterface>hardware_interface/EffortJointInterface</hardwareInterface>
        </joint>
        <actuator name="middle_finger_2_joint_motor">
            <mechanicalReduction>1</mechanicalReduction>
            <hardwareInterface>hardware_interface/EffortJointInterface</hardwareInterface>
        </actuator>
    </transmission>
    <transmission name="middle_finger_3_joint_trans">
        <type>transmission_interface/SimpleTransmission</type>
        <joint name="middle_finger_3_joint">
            <hardwareInterface>hardware_interface/EffortJointInterface</hardwareInterface>
        </joint>
        <actuator name="middle_finger_3_joint_motor">
            <mechanicalReduction>1</mechanicalReduction>
            <hardwareInterface>hardware_interface/EffortJointInterface</hardwareInterface>
        </actuator>
    </transmission>
    <transmission name="right_finger_2_joint_trans">
        <type>transmission_interface/SimpleTransmission</type>
        <joint name="right_finger_2_joint">
            <hardwareInterface>hardware_interface/EffortJointInterface</hardwareInterface>
        </joint>
        <actuator name="right_finger_2_joint_motor">
            <mechanicalReduction>1</mechanicalReduction>
            <hardwareInterface>hardware_interface/EffortJointInterface</hardwareInterface>
        </actuator>
    </transmission>
    <transmission name="right_finger_3_joint_trans">
        <type>transmission_interface/SimpleTransmission</type>
        <joint name="right_finger_3_joint">
            <hardwareInterface>hardware_interface/EffortJointInterface</hardwareInterface>
        </joint>
        <actuator name="right_finger_3_joint_motor">
            <mechanicalReduction>1</mechanicalReduction>
            <hardwareInterface>hardware_interface/EffortJointInterface</hardwareInterface>
        </actuator>
    </transmission>
    <gazebo>
        <plugin filename="libroboticsgroup_upatras_gazebo_mimic_joint_plugin.so" name="mimic_robotiq_140_1">
            <joint>left_finger_1_joint</joint>
            <mimicJoint>right_finger_1_joint</mimicJoint>
            <multiplier>-1.0</multiplier>
            <offset>0.0</offset>
            <maxEffort>5.0</maxEffort>
            <hasPID />
        </plugin>
        <plugin filename="libgazebo_grasp_fix.so" name="gazebo_grasp_fix">
            --&gt;
            <arm>
                <arm_name>my_robotiq_gripper</arm_name>
                <palm_link>bracelet_link</palm_link>
                Gazebo merges links connected by fixed joints, so here we would have put gripper_base_link but it is merged with Bracelet_Link internally
                <gripper_link>left_outer_finger</gripper_link>
                <gripper_link>right_outer_finger</gripper_link>
                <gripper_link>middle_outer_finger</gripper_link>
            </arm>
            <forces_angle_tolerance>100</forces_angle_tolerance>
            <update_rate>10</update_rate>
            <grip_count_threshold>3</grip_count_threshold>
            <max_grip_count>10</max_grip_count>
            <release_tolerance>0.001</release_tolerance>
            <disable_collisions_on_attach>false</disable_collisions_on_attach>
            <contact_topic>__default_topic__</contact_topic>
        </plugin>
    </gazebo>
    <gazebo>
        <plugin filename="libgazebo_ros_control.so" name="gazebo_ros_control">
            <legacyModeNS>true</legacyModeNS>
        </plugin>
    </gazebo>
    <transmission name="trans_right_finger_1_joint">
        <type>transmission_interface/SimpleTransmission</type>
        <joint name="right_finger_1_joint">
            <hardwareInterface>hardware_interface/EffortJointInterface</hardwareInterface>
        </joint>
        <actuator name="right_finger_1_joint_motor">
            <hardwareInterface>hardware_interface/EffortJointInterface</hardwareInterface>
            <mechanicalReduction>1</mechanicalReduction>
        </actuator>
    </transmission>
</robot>

