<?xml version="1.0"?>
<robot xmlns:xacro="http://ros.org/wiki/xacro">


  <!-- PALM LINK AND JOINT -->
  
  <link name="${prefix}palm_link">
    <inertial>
      <origin xyz="0 0 0.0386" />
      <mass value="1.0288" /><!-- density 1652.3 kg/m3 adjusted to have final total mass of 1.95 -->
      <inertia ixx="0.0011896" ixy="0.0" ixz="0.0" iyy="0.0011889" iyz="0.0" izz="0.0015636" />
    </inertial>
    <visual>
      <origin xyz="0 0 0" rpy="0 0 0" />
      <geometry>
        <mesh filename="package://kortex_description/grippers/robotiq_2f_140/meshes/visual/palm.stl" />
      </geometry>
      <material name="">
        <color rgba="0.1 0.1 0.1 1" />
      </material>
    </visual>
    <collision>
      <origin xyz="0 0 0" rpy="0 0 0" />
      <geometry>
        <mesh filename="package://kortex_description/grippers/robotiq_2f_140/meshes/collision/palm_collision.stl" />
      </geometry>
    </collision>
  </link>

  <joint name="${prefix}palm_joint" type="fixed">
      <parent link="${parent}"/>
      <child link="${prefix}palm_link"/>
      <origin rpy="0.0 0.0 ${pi / 2 }" xyz="0.0 0.0 0.0"/>
  </joint>

  <gazebo reference="${prefix}palm_link">
    <material>Gazebo/Black</material>  
  </gazebo>




  <!-- FINGER 1 LINK AND JOINTS -->

  <!-- FINGER 1 LINKS -->
  <xacro:macro name="finger_1" params="prefix fingerprefix stroke">
    <link name="${prefix}${fingerprefix}_finger_1">
      <inertial>
        <origin xyz="0.0 2.2105e-03 1.2155e-02" />
        <mass value="0.047" /> <!-- density of aluminum -->
        <inertia ixx="1.5889e-05" ixy="0.0" ixz="0.0" iyy="6.9350e-06" iyz="-4.7500e-07" izz="1.4915e-05" />
      </inertial>
      <visual>
        <origin xyz="0 0 0" rpy="0 0 0" />
        <geometry>
          <mesh filename="package://kortex_description/grippers/robotiq_2f_140/meshes/visual/knuckle.stl" />
        </geometry>
        <material name="">
          <color rgba="0.792156862745098 0.819607843137255 0.933333333333333 1" />
        </material>
      </visual>
      <collision>
        <origin xyz="0 0 0" rpy="0 0 0" />
        <geometry>
          <mesh filename="package://kortex_description/grippers/robotiq_2f_140/meshes/collision/knuckle_collision.stl" />
        </geometry>
      </collision>
    </link>
    <gazebo reference="${prefix}${fingerprefix}_finger_1">
      <visual>  
        <material>  
          <ambient>0.792156862745098 0.819607843137255 0.933333333333333 1</ambient>  
          <diffuse>0.792156862745098 0.819607843137255 0.933333333333333 1</diffuse>  
        </material>  
      </visual> 
    </gazebo>
  </xacro:macro>

  <!-- FINGER 1 JOINTS -->
  <xacro:macro name="left_finger_1_joint" params="prefix">
    <joint name="${prefix}left_finger_1_joint" type="revolute">
      <origin xyz="0.01905 0.033 0.0745" rpy="0 0 3.14159265" />
      <parent link="${prefix}palm_link" />
      <child link="${prefix}left_finger_1" />
      <axis xyz="0 0 1" />
      <limit effort="100" lower="0" upper="1.570796327" velocity="5"/>
    </joint>
    <xacro:finger_joints prefix="${prefix}" fingerprefix="left" reflect="1.0"/>
  </xacro:macro>

  <xacro:macro name="right_finger_1_joint" params="prefix">
    <joint name="${prefix}right_finger_1_joint" type="revolute">
      <origin xyz="0.01905 -0.033 0.0745" rpy="0 0 3.14159265" />
      <parent link="${prefix}palm_link" />
      <child link="${prefix}right_finger_1" />
      <axis xyz="0 0 1" />
      <limit effort="100" lower="0" upper="1.570796327" velocity="5"/>
    <mimic joint="${prefix}left_finger_1_joint" multiplier="-1" offset="0" />
    </joint>
    <xacro:finger_joints prefix="${prefix}" fingerprefix="right" reflect="-1.0"/>
  </xacro:macro>

  <xacro:macro name="middle_finger_1_joint" params="prefix">
    <joint name="${prefix}middle_finger_1_joint" type="fixed">
      <origin xyz="-0.03811 0 0.0745 " rpy="0 0 0" />
      <parent link="${prefix}palm_link" />
      <child link="${prefix}middle_finger_1" />
    </joint>
    <xacro:finger_joints prefix="${prefix}" fingerprefix="middle" reflect="-1.0"/>
  </xacro:macro>






  <!-- FINGER 2 LINKS AND JOINTS -->

  <!-- FINGER 2 LINKS -->
  <xacro:macro name="finger_2" params="prefix fingerprefix stroke">
    <link name="${prefix}${fingerprefix}_finger_2">
      <inertial>
        <origin xyz="0.0007467 -0.0000378 0.0430192" />
        <mass value="0.167" /> <!-- density of aluminum -->
        <inertia ixx="1.5920e-04" ixy="0.0" ixz="-2.3750e-08" iyy="1.5903e-04" iyz="9.3100e-06" izz="1.9142e-05" />
      </inertial>
      <visual>
        <origin xyz="0 0 0" rpy="0 0 0" />
        <geometry>
          <mesh filename="package://kortex_description/grippers/robotiq_2f_140/meshes/visual/finger.stl" />
        </geometry>
        <material name="">
          <color rgba="0.1 0.1 0.1 1" />
        </material>
      </visual>
      <collision>
        <origin xyz="0 0 0" rpy="0 0 0" />
        <geometry>
          <mesh filename="package://kortex_description/grippers/robotiq_2f_140/meshes/visual/finger.stl" />
        </geometry>
      </collision>
    </link>
    <gazebo reference="${prefix}${fingerprefix}_finger_2">
      <material>Gazebo/White</material>
    </gazebo>
  </xacro:macro>

  <!-- FINGER 2 JOINTS -->
  <xacro:macro name="finger_2_joints" params="prefix fingerprefix">
    <joint name="${prefix}${fingerprefix}_finger_2_joint" type="revolute">
      <origin xyz="0 0 0.0165" rpy="0 0 0" />
      <parent link="${prefix}${fingerprefix}_finger_1" />
      <child link="${prefix}${fingerprefix}_finger_2" />
      <axis xyz="0 1 0" />
      <limit effort="100" lower="-1.570796327" upper="1.570796327" velocity="5"/>
    </joint>
  </xacro:macro>





  <!-- FINGER 3 LINKS AND JOINTS -->

  <!-- FINGER 3 LINKS -->
  <xacro:macro name="finger_3" params="prefix fingerprefix stroke">
    <link name="${prefix}${fingerprefix}_finger_3">
      <inertial>
        <origin xyz="0.0007467 -0.0000378 0.0430192" />
        <mass value="0.0929" /> <!-- density of aluminum -->
        <inertia ixx="4.2323e-05" ixy="1.9000e-07" ixz="-5.2250e-07" iyy="3.9734e-05" iyz="5.7950e-06" izz="1.1210e-05" />
      </inertial>
      <visual>
        <origin xyz="0 0 0" rpy="0 0 0" />
        <geometry>
          <mesh filename="package://kortex_description/grippers/robotiq_2f_140/meshes/visual/finger_tip.stl" />
        </geometry>
        <material name="">
          <color rgba="0.1 0.1 0.1 1" />
        </material>
      </visual>
      <collision>
        <origin xyz="0 0 0" rpy="0 0 0" />
        <geometry>
          <mesh filename="package://kortex_description/grippers/robotiq_2f_140/meshes/visual/finger_tip.stl" />
        </geometry>
      </collision>
    </link>
    <gazebo reference="${prefix}${fingerprefix}_finger_3">
      <material>Gazebo/White</material>
    </gazebo>
  </xacro:macro>

  <!-- FINGER 3 JOINTS -->
  <xacro:macro name="finger_3_joints" params="prefix fingerprefix">
    <joint name="${prefix}${fingerprefix}_finger_3_joint" type="revolute">
      <origin xyz="0 0 0.0865" rpy="0 0 0" />
      <parent link="${prefix}${fingerprefix}_finger_2" />
      <child link="${prefix}${fingerprefix}_finger_3" />
      <axis xyz="0 1 0" />
      <limit effort="100" lower="-1.570796327" upper="1.570796327" velocity="5"/>
    </joint>
  </xacro:macro>





  <xacro:macro name="finger_joints" params="prefix fingerprefix reflect">
    <xacro:finger_2_joints prefix="${prefix}" fingerprefix="${fingerprefix}"/>
    <xacro:finger_3_joints prefix="${prefix}" fingerprefix="${fingerprefix}"/>
  </xacro:macro>

  <xacro:macro name="finger_links" params="prefix fingerprefix stroke">
    <xacro:finger_1 prefix="${prefix}" fingerprefix="${fingerprefix}" stroke="${stroke}"/>
    <xacro:finger_2 prefix="${prefix}" fingerprefix="${fingerprefix}" stroke="${stroke}"/>
    <xacro:finger_3 prefix="${prefix}" fingerprefix="${fingerprefix}" stroke="${stroke}"/>
  </xacro:macro>

  

  



  

  <xacro:macro name="robotiq_arg2f_140" params="parent prefix">
    <!-- Tool frame used by the arm -->
    <link name="${prefix}tool_frame"/>
    <joint name="${prefix}tool_frame_joint" type="fixed">
        <origin xyz="0 0 0.20" rpy="0 0 0" />
        <parent link="${parent}" />
        <child link="${prefix}tool_frame" />
        <axis xyz="0 0 0" />
    </joint>
    <!-- Gripper description -->
    <xacro:finger_links prefix="${prefix}" fingerprefix="left" stroke="140"/>
    <xacro:finger_links prefix="${prefix}" fingerprefix="right" stroke="140"/>
    <xacro:finger_links prefix="${prefix}" fingerprefix="middle" stroke="140"/>
    <xacro:left_finger_1_joint prefix="${prefix}"/>
    <xacro:right_finger_1_joint prefix="${prefix}"/>
    <xacro:middle_finger_1_joint prefix="${prefix}"/>
    <!-- Transmissions are loaded in the generic kortex xacro when simulation is enabled -->
    <!-- <xacro:robotiq_arg2f_transmission prefix="${prefix}"/> -->
  </xacro:macro>
</robot>
